Workbook

Sheet Tableau de Bord
A1: TABLEAU DE BORD - ACHATS KARITE & FOURNISSEURS
A4: BONS DE COMMANDE EMIS | C4: CAMIONS DECHARGES | E4: EN ATTENTE DE DECHARGEMENT | G4: POIDS NET TOTAL LIVRE (KG) | I4: MONTANT TOTAL ACHATS (FCFA) | K4: SOLDE RESTANT DU (FCFA)
A5: =COUNTA('Bons de Commande'!D5:D1048576) | C5: =COUNTA('Commandes Dechargees'!D5:D1048576) | E5: =COUNTIF('Bons de Commande'!J5:J1048576,"EN ATTENTE") | G5: =SUM('Commandes Dechargees'!H5:H1048576) | I5: =SUM('Commandes Dechargees'!K5:K1048576) | K5: =SUM('Commandes Dechargees'!M5:M1048576)
A9: MONTANT PAYE (FCFA) | C9: % MONTANT PAYE | E9: LIVRAISONS NON PAYEES | G9: LIVRAISONS PARTIELLEMENT PAYEES | I9: FOURNISSEURS ACTIFS | K9: ECARTS PO/CAMION A VERIFIER
A10: =SUM('Commandes Dechargees'!L5:L1048576) | C10: =A10/I5 | E10: =COUNTIF('Commandes Dechargees'!N5:N1048576,"NON PAYE") | G10: =COUNTIF('Commandes Dechargees'!N5:N1048576,"PARTIEL") | I10: =COUNTA(_xlfn.UNIQUE('Commandes Dechargees'!D5:D1048576)) | K10: =COUNTIF('Bons de Commande'!D5:D1048576,"NONE")

Sheet Bons de Commande
C1: BONS DE COMMANDE
C4: Date | D4: N° BC | E4: Code Frs | F4: Fournisseur | G4: N° Camion | H4: Contact Chauffeur | I4: Order QTY(MT) | J4: Verdict Labo | K4: Statut Livraison
C5: 46239 | D5: 0001-BC-SHEA/NAP-2026 | E5: FRS00001 | F5: =_xlfn.XLOOKUP(Table1[[#This Row],[Code Frs]],'CODE FRS'!B:B,'CODE FRS'!C:C) | G5: CA7583RB/AP2290RB | H5: 197257982 | I5: 50 | J5: APROUVE | K5: =_xlfn.IFNA(_xlfn.XLOOKUP(Table1[[#This Row],[N° BC]],'Commandes Dechargees'!B:B,'Commandes Dechargees'!P:P),"EN ATTENTE DE DECHARGEMENT")
C6: 46241 | D6: 0002-BC-SHEA/NAP-2026 | E6: FRS00002 | F6: =_xlfn.XLOOKUP(Table1[[#This Row],[Code Frs]],'CODE FRS'!B:B,'CODE FRS'!C:C) | G6: BL6012RB/AS9458RB | H6: 194252204 | I6: 50 | J6: APROUVE | K6: =_xlfn.IFNA(_xlfn.XLOOKUP(Table1[[#This Row],[N° BC]],'Commandes Dechargees'!B:B,'Commandes Dechargees'!P:P),"EN ATTENTE DE DECHARGEMENT")
C7: 46242 | D7: 0003-BC-SHEA/NAP-2026 | E7: FRS00001 | F7: =_xlfn.XLOOKUP(Table1[[#This Row],[Code Frs]],'CODE FRS'!B:B,'CODE FRS'!C:C) | G7: BU4105RB/BS8146RB | H7: 162958703 | I7: 50 | J7: APROUVE | K7: =_xlfn.IFNA(_xlfn.XLOOKUP(Table1[[#This Row],[N° BC]],'Commandes Dechargees'!B:B,'Commandes Dechargees'!P:P),"EN ATTENTE DE DECHARGEMENT")
C8: 46244 | D8: 0004-BC-SHEA/NAP-2026 | E8: FRS00001 | F8: =_xlfn.XLOOKUP(Table1[[#This Row],[Code Frs]],'CODE FRS'!B:B,'CODE FRS'!C:C) | G8: BT4680RB/BJ0826RB | H8: 197881184 | I8: 50 | J8: REJETE | K8: REJETE
C9: 46244 | D9: 0005-BC-SHEA/NAP-2026 | E9: FRS00001 | F9: =_xlfn.XLOOKUP(Table1[[#This Row],[Code Frs]],'CODE FRS'!B:B,'CODE FRS'!C:C) | G9: CD0085RB/AN4107RB | H9: 196026166 | I9: 45 | J9: APROUVE | K9: =_xlfn.IFNA(_xlfn.XLOOKUP(Table1[[#This Row],[N° BC]],'Commandes Dechargees'!B:B,'Commandes Dechargees'!P:P),"EN ATTENTE DE DECHARGEMENT")
C10: 46244 | D10: 0006-BC-SHEA/NAP-2026 | E10: FRS00003 | F10: =_xlfn.XLOOKUP(Table1[[#This Row],[Code Frs]],'CODE FRS'!B:B,'CODE FRS'!C:C) | G10: BD6541RB/BD6542RB | H10: 140534093 | I10: 50 | J10: REJETE | K10: REJETE
C11: 46244 | D11: 0007-BC-SHEA/NAP-2026 | E11: FRS00002 | F11: =_xlfn.XLOOKUP(Table1[[#This Row],[Code Frs]],'CODE FRS'!B:B,'CODE FRS'!C:C) | G11: CL7219RB/CH7144RB | H11: 153139048 | I11: 50 | J11: APROUVE | K11: =_xlfn.IFNA(_xlfn.XLOOKUP(Table1[[#This Row],[N° BC]],'Commandes Dechargees'!B:B,'Commandes Dechargees'!P:P),"EN ATTENTE DE DECHARGEMENT")
C12: 46244 | D12: 0008-BC-SHEA/NAP-2026 | E12: FRS00004 | F12: =_xlfn.XLOOKUP(Table1[[#This Row],[Code Frs]],'CODE FRS'!B:B,'CODE FRS'!C:C) | G12: CH7143RB | H12: 197275693 | I12: 50 | J12: EN ATTENTE | K12: =_xlfn.IFNA(_xlfn.XLOOKUP(Table1[[#This Row],[N° BC]],'Commandes Dechargees'!B:B,'Commandes Dechargees'!P:P),"EN ATTENTE DE DECHARGEMENT")
C13: 46244 | D13: 0009-BC-SHEA/NAP-2026 | E13: FRS00002 | F13: =_xlfn.XLOOKUP(Table1[[#This Row],[Code Frs]],'CODE FRS'!B:B,'CODE FRS'!C:C) | G13: CH7143RB/BU4686RB | H13: 196804429 | I13: 50 | J13: APROUVE | K13: =_xlfn.IFNA(_xlfn.XLOOKUP(Table1[[#This Row],[N° BC]],'Commandes Dechargees'!B:B,'Commandes Dechargees'!P:P),"EN ATTENTE DE DECHARGEMENT")
C14: 46246 | D14: 0010-BC-SHEA/NAP-2026 | E14: FRS00003 | F14: =_xlfn.XLOOKUP(Table1[[#This Row],[Code Frs]],'CODE FRS'!B:B,'CODE FRS'!C:C) | G14: BM5662RB/BB9141RB | H14: - | I14: 50 | J14: EN ATTENTE | K14: =_xlfn.IFNA(_xlfn.XLOOKUP(Table1[[#This Row],[N° BC]],'Commandes Dechargees'!B:B,'Commandes Dechargees'!P:P),"EN ATTENTE DE DECHARGEMENT")
C15: 46246 | D15: 0011-BC-SHEA/NAP-2026 | E15: FRS00002 | F15: =_xlfn.XLOOKUP(Table1[[#This Row],[Code Frs]],'CODE FRS'!B:B,'CODE FRS'!C:C) | G15: BZ6773RB/AM0814RB | H15: 164555251 | I15: 50 | J15: APROUVE | K15: =_xlfn.IFNA(_xlfn.XLOOKUP(Table1[[#This Row],[N° BC]],'Commandes Dechargees'!B:B,'Commandes Dechargees'!P:P),"EN ATTENTE DE DECHARGEMENT")
C16: 46246 | D16: 0012-BC-SHEA/NAP-2026 | E16: FRS00004 | F16: =_xlfn.XLOOKUP(Table1[[#This Row],[Code Frs]],'CODE FRS'!B:B,'CODE FRS'!C:C) | G16: CB0469RB/BZ8567RB | H16: 19063102 | I16: 50 | J16: REJETE | K16: REJETE
C17: 46247 | D17: 0013-BC-SHEA/NAP-2026 | E17: FRS00003 | F17: =_xlfn.XLOOKUP(Table1[[#This Row],[Code Frs]],'CODE FRS'!B:B,'CODE FRS'!C:C) | G17: AN3809RB/AS6857RB | H17: 140296383 | I17: 50 | J17: REJETE | K17: REJETE
C18: 46247 | D18: 0014-BC-SHEA/NAP-2026 | E18: FRS00003 | F18: =_xlfn.XLOOKUP(Table1[[#This Row],[Code Frs]],'CODE FRS'!B:B,'CODE FRS'!C:C) | G18: BM5662RB/BB9141RB | H18: 196042763 | I18: 50 | J18: EN ATTENTE | K18: =_xlfn.IFNA(_xlfn.XLOOKUP(Table1[[#This Row],[N° BC]],'Commandes Dechargees'!B:B,'Commandes Dechargees'!P:P),"EN ATTENTE DE DECHARGEMENT")
C19: 46247 | D19: 0015-BC-SHEA/NAP-2026 | E19: FRS00005 | F19: =_xlfn.XLOOKUP(Table1[[#This Row],[Code Frs]],'CODE FRS'!B:B,'CODE FRS'!C:C) | G19: AZ4227RB/AE4983RB | H19: 197742448 | I19: 50 | J19: APROUVE | K19: =_xlfn.IFNA(_xlfn.XLOOKUP(Table1[[#This Row],[N° BC]],'Commandes Dechargees'!B:B,'Commandes Dechargees'!P:P),"EN ATTENTE DE DECHARGEMENT")
C20: 46247 | D20: 0016-BC-SHEA/NAP-2026 | E20: FRS00005 | F20: =_xlfn.XLOOKUP(Table1[[#This Row],[Code Frs]],'CODE FRS'!B:B,'CODE FRS'!C:C) | G20: BF4794RB/BG3245RB | H20: 148696900 | I20: 50 | J20: REJETE | K20: REJETE
C21: 46247 | D21: 0017-BC-SHEA/NAP-2026 | E21: FRS00006 | F21: =_xlfn.XLOOKUP(Table1[[#This Row],[Code Frs]],'CODE FRS'!B:B,'CODE FRS'!C:C) | G21: BN9320RB/1254RB | H21: 198209181 | I21: 45 | J21: APROUVE | K21: =_xlfn.IFNA(_xlfn.XLOOKUP(Table1[[#This Row],[N° BC]],'Commandes Dechargees'!B:B,'Commandes Dechargees'!P:P),"EN ATTENTE DE DECHARGEMENT")
C22: 46247 | D22: 0018-BC-SHEA/NAP-2026 | E22: FRS00006 | F22: =_xlfn.XLOOKUP(Table1[[#This Row],[Code Frs]],'CODE FRS'!B:B,'CODE FRS'!C:C) | G22: CA0713RB/BH0362RB | H22: 193946883 | I22: 45 | J22: APROUVE | K22: =_xlfn.IFNA(_xlfn.XLOOKUP(Table1[[#This Row],[N° BC]],'Commandes Dechargees'!B:B,'Commandes Dechargees'!P:P),"EN ATTENTE DE DECHARGEMENT")
C23: 46247 | D23: 0019-BC-SHEA/NAP-2026 | E23: FRS00007 | F23: =_xlfn.XLOOKUP(Table1[[#This Row],[Code Frs]],'CODE FRS'!B:B,'CODE FRS'!C:C) | G23: CK9046RB/CB6301RB | H23: 196562615 | I23: 50 | J23: REJETE | K23: REJETE
C24: 46247 | D24: 0020-BC-SHEA/NAP-2026 | E24: FRS00007 | F24: =_xlfn.XLOOKUP(Table1[[#This Row],[Code Frs]],'CODE FRS'!B:B,'CODE FRS'!C:C) | G24: BS4562RB/AY6037RB | H24: 197703410 | I24: 50 | J24: REJETE | K24: REJETE
C25: 46247 | D25: 0021-BC-SHEA/NAP-2026 | E25: FRS00001 | F25: =_xlfn.XLOOKUP(Table1[[#This Row],[Code Frs]],'CODE FRS'!B:B,'CODE FRS'!C:C) | G25: CB6228RB/CC4818RB | H25: - | I25: 50 | J25: APROUVE | K25: =_xlfn.IFNA(_xlfn.XLOOKUP(Table1[[#This Row],[N° BC]],'Commandes Dechargees'!B:B,'Commandes Dechargees'!P:P),"EN ATTENTE DE DECHARGEMENT")
C26: 46248 | D26: 0022-BC-SHEA/NAP-2026 | E26: FRS00009 | F26: =_xlfn.XLOOKUP(Table1[[#This Row],[Code Frs]],'CODE FRS'!B:B,'CODE FRS'!C:C) | G26: BB9793RB/BD3472RB | H26: 197114423 | I26: 50 | J26: APROUVE | K26: =_xlfn.IFNA(_xlfn.XLOOKUP(Table1[[#This Row],[N° BC]],'Commandes Dechargees'!B:B,'Commandes Dechargees'!P:P),"EN ATTENTE DE DECHARGEMENT")
C27: 46248 | D27: 0023-BC-SHEA/NAP-2026 | E27: FRS00010 | F27: =_xlfn.XLOOKUP(Table1[[#This Row],[Code Frs]],'CODE FRS'!B:B,'CODE FRS'!C:C) | G27: BR9516RB/BD8968RB | H27: 162835009 | I27: 40 | J27: EN ATTENTE | K27: =_xlfn.IFNA(_xlfn.XLOOKUP(Table1[[#This Row],[N° BC]],'Commandes Dechargees'!B:B,'Commandes Dechargees'!P:P),"EN ATTENTE DE DECHARGEMENT")
C28: 46248 | D28: 0024-BC-SHEA/NAP-2026 | E28: FRS00011 | F28: =_xlfn.XLOOKUP(Table1[[#This Row],[Code Frs]],'CODE FRS'!B:B,'CODE FRS'!C:C) | G28: BY2229RB/BD4807RB | H28: 140861444 | I28: 50 | J28: REJETE | K28: REJETE
C29: 46248 | D29: 0025-BC-SHEA/NAP-2026 | E29: FRS00012 | F29: =_xlfn.XLOOKUP(Table1[[#This Row],[Code Frs]],'CODE FRS'!B:B,'CODE FRS'!C:C) | G29: CF7090RB/AZ1276RB | H29: 197365988 | I29: 45 | J29: ANNULE | K29: =_xlfn.IFNA(_xlfn.XLOOKUP(Table1[[#This Row],[N° BC]],'Commandes Dechargees'!B:B,'Commandes Dechargees'!P:P),"EN ATTENTE DE DECHARGEMENT")
C30: 46248 | D30: 0026-BC-SHEA/NAP-2026 | E30: FRS00001 | F30: =_xlfn.XLOOKUP(Table1[[#This Row],[Code Frs]],'CODE FRS'!B:B,'CODE FRS'!C:C) | G30: CG9072RB/CC4676RB | H30: 141192392 | I30: 35 | J30: APROUVE | K30: =_xlfn.IFNA(_xlfn.XLOOKUP(Table1[[#This Row],[N° BC]],'Commandes Dechargees'!B:B,'Commandes Dechargees'!P:P),"EN ATTENTE DE DECHARGEMENT")
C31: 46248 | D31: 0027-BC-SHEA/NAP-2026 | E31: FRS00013 | F31: =_xlfn.XLOOKUP(Table1[[#This Row],[Code Frs]],'CODE FRS'!B:B,'CODE FRS'!C:C) | G31: BA0693RB/BG9156RB | H31: 162765372 | I31: 45 | J31: APROUVE | K31: =_xlfn.IFNA(_xlfn.XLOOKUP(Table1[[#This Row],[N° BC]],'Commandes Dechargees'!B:B,'Commandes Dechargees'!P:P),"EN ATTENTE DE DECHARGEMENT")
C32: 46248 | D32: 0028-BC-SHEA/NAP-2026 | E32: FRS00003 | F32: =_xlfn.XLOOKUP(Table1[[#This Row],[Code Frs]],'CODE FRS'!B:B,'CODE FRS'!C:C) | G32: BS9080RB/BB2652RB | H32: 163435902 | I32: 50 | J32: REJETE | K32: REJETE
C33: 46248 | D33: 0029-BC-SHEA/NAP-2026 | E33: FRS00009 | F33: =_xlfn.XLOOKUP(Table1[[#This Row],[Code Frs]],'CODE FRS'!B:B,'CODE FRS'!C:C) | G33: BX9971RB | H33: 197291416 | I33: 50 | J33: REJETE | K33: REJETE
C34: 46248 | D34: 0030-BC-SHEA/NAP-2026 | E34: FRS00009 | F34: =_xlfn.XLOOKUP(Table1[[#This Row],[Code Frs]],'CODE FRS'!B:B,'CODE FRS'!C:C) | G34: BA8553RB/BB0493RB | H34: 167127112 | I34: 50 | J34: REJETE | K34: REJETE
C35: 46249 | D35: 0031-BC-SHEA/NAP-2026 | E35: FRS00014 | F35: =_xlfn.XLOOKUP(Table1[[#This Row],[Code Frs]],'CODE FRS'!B:B,'CODE FRS'!C:C) | G35: BS4324RB /4374RB | H35: 194304813 | I35: 55 | J35: EN ATTENTE | K35: =_xlfn.IFNA(_xlfn.XLOOKUP(Table1[[#This Row],[N° BC]],'Commandes Dechargees'!B:B,'Commandes Dechargees'!P:P),"EN ATTENTE DE DECHARGEMENT")
C36: 46249 | D36: 0032-BC-SHEA/NAP-2026 | E36: FRS00015 | F36: =_xlfn.XLOOKUP(Table1[[#This Row],[Code Frs]],'CODE FRS'!B:B,'CODE FRS'!C:C) | G36: AY3969RB/AD0138RB | H36: 143756265 | I36: 50 | J36: APROUVE | K36: =_xlfn.IFNA(_xlfn.XLOOKUP(Table1[[#This Row],[N° BC]],'Commandes Dechargees'!B:B,'Commandes Dechargees'!P:P),"EN ATTENTE DE DECHARGEMENT")
C37: 46249 | D37: 0033-BC-SHEA/NAP-2026 | E37: FRS00016 | F37: =_xlfn.XLOOKUP(Table1[[#This Row],[Code Frs]],'CODE FRS'!B:B,'CODE FRS'!C:C) | G37: AP7150RB/AL0466RB | H37: 0197436870 ET 0141422926 | I37: 50 | J37: APROUVE | K37: =_xlfn.IFNA(_xlfn.XLOOKUP(Table1[[#This Row],[N° BC]],'Commandes Dechargees'!B:B,'Commandes Dechargees'!P:P),"EN ATTENTE DE DECHARGEMENT")
C38: 46249 | D38: 0034-BC-SHEA/NAP-2026 | E38: FRS00012 | F38: =_xlfn.XLOOKUP(Table1[[#This Row],[Code Frs]],'CODE FRS'!B:B,'CODE FRS'!C:C) | G38: AZ8985RB/AN0577RB | H38: 197760647 | I38: 45 | J38: REJETE | K38: REJETE
C39: 46249 | D39: 0035-BC-SHEA/NAP-2026 | E39: FRS00011 | F39: =_xlfn.XLOOKUP(Table1[[#This Row],[Code Frs]],'CODE FRS'!B:B,'CODE FRS'!C:C) | G39: BU9958RB/AL0499RB | H39: 01 97502513 ET 0144635683 | I39: 50 | J39: REJETE | K39: REJETE
C40: 46249 | D40: 0036-BC-SHEA/NAP-2026 | E40: FRS00011 | F40: =_xlfn.XLOOKUP(Table1[[#This Row],[Code Frs]],'CODE FRS'!B:B,'CODE FRS'!C:C) | G40: CE6743RB/CC9634RB | H40: 01 97502513 ET 0151084124 | I40: 50 | J40: EN ATTENTE | K40: =_xlfn.IFNA(_xlfn.XLOOKUP(Table1[[#This Row],[N° BC]],'Commandes Dechargees'!B:B,'Commandes Dechargees'!P:P),"EN ATTENTE DE DECHARGEMENT")
C41: 46249 | D41: 0037-BC-SHEA/NAP-2026 | E41: FRS00011 | F41: =_xlfn.XLOOKUP(Table1[[#This Row],[Code Frs]],'CODE FRS'!B:B,'CODE FRS'!C:C) | G41: CC2786RB/AT7647RB | H41: 01 97502513 ET 0159551025 | I41: 51 | J41: ANNULE | K41: =_xlfn.IFNA(_xlfn.XLOOKUP(Table1[[#This Row],[N° BC]],'Commandes Dechargees'!B:B,'Commandes Dechargees'!P:P),"EN ATTENTE DE DECHARGEMENT")
C42: 46249 | D42: 0038-BC-SHEA/NAP-2026 | E42: FRS00001 | F42: =_xlfn.XLOOKUP(Table1[[#This Row],[Code Frs]],'CODE FRS'!B:B,'CODE FRS'!C:C) | G42: CJ4249RB/AU9045RB | H42: 0195036013 ET 0196902499 | I42: 50 | J42: EN ATTENTE | K42: =_xlfn.IFNA(_xlfn.XLOOKUP(Table1[[#This Row],[N° BC]],'Commandes Dechargees'!B:B,'Commandes Dechargees'!P:P),"EN ATTENTE DE DECHARGEMENT")
...

Sheet CODE FRS
A1: CODE FOURNISSEUR
B3: CODE | C3: NOM DU FOURNISSEUR | F3: Verdict Labo | G3: Statut Livraison
B4: FRS00001 | C4: TCHANIGA SAMSON | F4: APROUVE | G4: DECHARGE
B5: FRS00002 | C5: ISMAEL WASSIOU/ Mme ELISABETH | F5: REJETE | G5: REJETE
B6: FRS00003 | C6: BADAROU SAID | F6: EN ATTENTE | G6: EN ATTENTE DE DECHARGEMENT
B7: FRS00004 | C7: ISMAEL WASSIOU | F7: ANNULE | G7: ANNULE
B8: FRS00005 | C8: ALLASSANE MARWANE
B9: FRS00006 | C9: VLAVONOU PIERRE
B10: FRS00007 | C10: BRISSO BIO ALIDOU
B11: FRS00008 | C11: HERVE KOBOLOU
B12: FRS00009 | C12: GOUDO DOSSOU ROMAIN
B13: FRS00010 | C13: COMLAN MAHOUSSE JOSPIN
B14: FRS00011 | C14: CHIGBLO FERDINAND
B15: FRS00012 | C15: ROLAND ADANHONDJI
B16: FRS00013 | C16: MENSAH DANIEL JOEL
B17: FRS00014 | C17: FIOGBE
B18: FRS00015 | C18: GBAGBE MATHIAS
B19: FRS00016 | C19: AHEGNI CASIMIR
... B62: FRS00059 | C62: MR MOUSSA

Sheet Commandes Dechargees
A1: COMMANDES DECHARGEES & PAIEMENTS
H3: =SUBTOTAL(9,Table2[Poids Net (KG)]) | I3: =SUBTOTAL(9,Table2[Nb Sacs]) | J3: =AVERAGE(Table2[PU (FCFA/KG)]) | K3: =SUBTOTAL(9,Table2[Montant Du]) | L3: =SUBTOTAL(9,Table2[Montant Paye]) | M3: =SUBTOTAL(9,Table2[Solde Restant])
A4: Date Dechargement | B4: N° BC | C4: Transaction | D4: Code Frs | E4: Fournisseur | F4: N° Camion | G4: WEIGHMENT TICKET | H4: Poids Net (KG) | I4: Nb Sacs | J4: PU (FCFA/KG) | K4: Montant Du | L4: Montant Paye | M4: Solde Restant | N4: Statut Paiement | O4: Bon de paiement | P4: Statut Livraison | Q4: Lieu Stockage
A5: 46245 | B5: 0001-BC-SHEA/NAP-2026 | C5: 1004 | D5: FRS00001 | E5: =_xlfn.XLOOKUP(D5,'CODE FRS'!B:B,'CODE FRS'!C:C) | F5: CA7583RB/AP2290RB | G5: 34650 | H5: 47300 | I5: 452 | J5: 330 | K5: =H5*J5 | L5: =6000000+9609000 | M5: =K5-L5 | N5: {=_xlfn.IFNA(_xlfn.IFS(M5=0,"PAYE",K5=M5,"NON PAYE"),"PARTIEL")} | O5: CHQ-0129-2026 & CHQ-0138-2026 | P5: DECHARGE | Q5: GDIZ
A6: 46244 | B6: 0002-BC-SHEA/NAP-2026 | C6: 1003 | D6: FRS00002 | E6: =_xlfn.XLOOKUP(D6,'CODE FRS'!B:B,'CODE FRS'!C:C) | F6: BL6012RB/AS9458RB | G6: 34599 | H6: 49380 | I6: 467 | J6: 330 | K6: =H6*J6 | L6: 16295400 | M6: =K6-L6 | N6: {=_xlfn.IFNA(_xlfn.IFS(M6=0,"PAYE",K6=M6,"NON PAYE"),"PARTIEL")} | O6: CHQ-0133-2026 | P6: DECHARGE | Q6: GDIZ
A7: 46245 | B7: 0003-BC-SHEA/NAP-2026 | C7: 1001 | D7: FRS00001 | E7: =_xlfn.XLOOKUP(D7,'CODE FRS'!B:B,'CODE FRS'!C:C) | F7: BU4105RB/BS8146RB | G7: 34658 | H7: 50160 | I7: 490 | J7: 330 | K7: =H7*J7 | L7: 16552800 | M7: =K7-L7 | N7: {=_xlfn.IFNA(_xlfn.IFS(M7=0,"PAYE",K7=M7,"NON PAYE"),"PARTIEL")} | O7: CHQ-0131-2026 | P7: DECHARGE | Q7: GDIZ
A8: 46247 | B8: 0007-BC-SHEA/NAP-2026 | C8: 1002 | D8: FRS00002 | E8: =_xlfn.XLOOKUP(D8,'CODE FRS'!B:B,'CODE FRS'!C:C) | F8: CL7219RB/CH7144RB | G8: 34726 | H8: 49600 | I8: 508 | J8: 330 | K8: =H8*J8 | L8: 0 | M8: =K8-L8 | N8: {=_xlfn.IFNA(_xlfn.IFS(M8=0,"PAYE",K8=M8,"NON PAYE"),"PARTIEL")} | P8: DECHARGE | Q8: GDIZ
A9: 46248 | B9: 0005-BC-SHEA/NAP-2026 | C9: 1005 | D9: FRS00001 | E9: =_xlfn.XLOOKUP(D9,'CODE FRS'!B:B,'CODE FRS'!C:C) | F9: CD0085RB/AN4107RB | G9: 34768 | H9: 40720 | I9: 370 | J9: 320 | K9: =H9*J9 | L9: 13030400 | M9: =K9-L9 | N9: {=_xlfn.IFNA(_xlfn.IFS(M9=0,"PAYE",K9=M9,"NON PAYE"),"PARTIEL")} | O9: CHQ-0151-2026 | P9: DECHARGE | Q9: GDIZ
A10: 46248 | C10: 1006 | D10: FRS00021 | E10: =_xlfn.XLOOKUP(D10,'CODE FRS'!B:B,'CODE FRS'!C:C) | F10: CE1927RB/BC7835RB | G10: 34753 | H10: 47500 | I10: 448 | J10: 330 | K10: =H10*J10 | L10: =7000000+8675000 | M10: =K10-L10 | N10: {=_xlfn.IFNA(_xlfn.IFS(M10=0,"PAYE",K10=M10,"NON PAYE"),"PARTIEL")} | O10: CHQ-0139-2026 & CHQ-0146-2026 | P10: DECHARGE | Q10: GDIZ
A11: 46248 | B11: 0009-BC-SHEA/NAP-2026 | C11: 1007 | D11: FRS00002 | E11: =_xlfn.XLOOKUP(D11,'CODE FRS'!B:B,'CODE FRS'!C:C) | F11: CH7143RB/BU4686RB | G11: 34762 | H11: 50120 | I11: 490 | J11: 330 | K11: =H11*J11 | L11: 16539600 | M11: =K11-L11 | N11: {=_xlfn.IFNA(_xlfn.IFS(M11=0,"PAYE",K11=M11,"NON PAYE"),"PARTIEL")} | O11: CHQ-0133-2026 | P11: DECHARGE | Q11: GDIZ
A12: 46249 | B12: 0018-BC-SHEA/NAP-2026 | C12: 1008 | D12: FRS00006 | E12: =_xlfn.XLOOKUP(D12,'CODE FRS'!B:B,'CODE FRS'!C:C) | F12: CA0713RB/BH0362RB | G12: 34786 | H12: 39240 | I12: 367 | J12: 330 | K12: =H12*J12 | L12: 12949200 | M12: =K12-L12 | N12: {=_xlfn.IFNA(_xlfn.IFS(M12=0,"PAYE",K12=M12,"NON PAYE"),"PARTIEL")} | O12: CHQ-0136-2026 | P12: DECHARGE | Q12: GDIZ
A13: 46251 | B13: 0021-BC-SHEA/NAP-2026 | C13: 1009 | D13: FRS00001 | E13: =_xlfn.XLOOKUP(D13,'CODE FRS'!B:B,'CODE FRS'!C:C) | F13: CB6228RB/CC4818RB | G13: 34820 | H13: 49640 | I13: 467 | J13: 330 | K13: =H13*J13 | L13: 16381200 | M13: =K13-L13 | N13: {=_xlfn.IFNA(_xlfn.IFS(M13=0,"PAYE",K13=M13,"NON PAYE"),"PARTIEL")} | O13: CHQ-0138-2026 | P13: DECHARGE | Q13: GDIZ
A14: 46251 | B14: 0026-BC-SHEA/NAP-2026 | C14: 1010 | D14: FRS00001 | E14: =_xlfn.XLOOKUP(D14,'CODE FRS'!B:B,'CODE FRS'!C:C) | F14: CG9072RB/CC4676RB | G14: 34823 | H14: 30320 | I14: 292 | J14: 330 | K14: =H14*J14 | L14: =8000000+2005600 | M14: =K14-L14 | N14: {=_xlfn.IFNA(_xlfn.IFS(M14=0,"PAYE",K14=M14,"NON PAYE"),"PARTIEL")} | O14: CHQ-0151-2026 | P14: DECHARGE | Q14: GDIZ
A15: 46251 | B15: 0011-BC-SHEA/NAP-2026 | C15: 1011 | D15: FRS00002 | E15: =_xlfn.XLOOKUP(D15,'CODE FRS'!B:B,'CODE FRS'!C:C) | F15: BZ6773RB/AN0814RB | G15: 34816 | H15: 47140 | I15: 495 | J15: 330 | K15: =H15*J15 | L15: 0 | M15: =K15-L15 | N15: {=_xlfn.IFNA(_xlfn.IFS(M15=0,"PAYE",K15=M15,"NON PAYE"),"PARTIEL")} | P15: DECHARGE | Q15: GDIZ
A16: 46251 | B16: 0015-BC-SHEA/NAP-2026 | C16: 1012 | D16: FRS00005 | E16: =_xlfn.XLOOKUP(D16,'CODE FRS'!B:B,'CODE FRS'!C:C) | F16: AZ4227RB/AE4983RB | G16: 34817 | H16: 46060 | I16: 470 | J16: 330 | K16: =H16*J16 | L16: 15199800 | M16: =K16-L16 | N16: {=_xlfn.IFNA(_xlfn.IFS(M16=0,"PAYE",K16=M16,"NON PAYE"),"PARTIEL")} | O16: CHQ-0158-2026 | P16: DECHARGE | Q16: GDIZ
A17: 46252 | B17: 0048-BC-SHEA/NAP-2026 | C17: 1013 | D17: FRS00001 | E17: =_xlfn.XLOOKUP(D17,'CODE FRS'!B:B,'CODE FRS'!C:C) | F17: CE6019RB/CE6020RB | G17: 34861 | H17: 47340 | I17: 442 | J17: 330 | K17: =H17*J17 | L17: 15622200 | M17: =K17-L17 | N17: {=_xlfn.IFNA(_xlfn.IFS(M17=0,"PAYE",K17=M17,"NON PAYE"),"PARTIEL")} | O17: CHQ-0144-2026 | P17: DECHARGE | Q17: GDIZ
A18: 46252 | C18: 1014 | D18: FRS00006 | E18: =_xlfn.XLOOKUP(D18,'CODE FRS'!B:B,'CODE FRS'!C:C) | F18: CB5092RB/AG6029RB | G18: 34848 | H18: 43820 | I18: 408 | J18: 330 | K18: =H18*J18 | L18: 14460600 | M18: =K18-L18 | N18: {=_xlfn.IFNA(_xlfn.IFS(M18=0,"PAYE",K18=M18,"NON PAYE"),"PARTIEL")} | O18: CHQ-0147-2026 | P18: DECHARGE | Q18: GDIZ
A19: 46252 | B19: 0017-BC-SHEA/NAP-2026 | C19: 1015 | D19: FRS00006 | E19: =_xlfn.XLOOKUP(D19,'CODE FRS'!B:B,'CODE FRS'!C:C) | F19: BN9320RB/BC1254RB | G19: 34849 | H19: 40020 | I19: 392 | J19: 330 | K19: =H19*J19 | L19: 13206600 | M19: =K19-L19 | N19: {=_xlfn.IFNA(_xlfn.IFS(M19=0,"PAYE",K19=M19,"NON PAYE"),"PARTIEL")} | O19: CHQ-0152-2026 | P19: DECHARGE | Q19: GDIZ
A20: 46252 | C20: 1016 | D20: FRS00006 | E20: =_xlfn.XLOOKUP(D20,'CODE FRS'!B:B,'CODE FRS'!C:C) | F20: CC8393RB/CC8391RB | G20: 34847 | H20: 45460 | I20: 436 | J20: 330 | K20: =H20*J20 | L20: 15001800 | M20: =K20-L20 | N20: {=_xlfn.IFNA(_xlfn.IFS(M20=0,"PAYE",K20=M20,"NON PAYE"),"PARTIEL")} | O20: CHQ-0145-2026 | P20: DECHARGE | Q20: GDIZ
A21: 46253 | B21: 0039-BC-SHEA/NAP-2026 | C21: 1017 | D21: FRS00017 | E21: =_xlfn.XLOOKUP(D21,'CODE FRS'!B:B,'CODE FRS'!C:C) | F21: CB2032RB/CB1943RB | G21: 34870 | H21: 31360 | I21: 290 | J21: 332 | K21: =H21*J21 | L21: 10411520 | M21: =K21-L21 | N21: {=_xlfn.IFNA(_xlfn.IFS(M21=0,"PAYE",K21=M21,"NON PAYE"),"PARTIEL")} | O21: CHQ-0149-2026 | P21: DECHARGE | Q21: GDIZ
A22: 46253 | C22: 1018 | D22: FRS00024 | E22: =_xlfn.XLOOKUP(D22,'CODE FRS'!B:B,'CODE FRS'!C:C) | F22: CG9846RB/CG9873RB | G22: 34868 | H22: 31960 | I22: 332 | J22: 330 | K22: =H22*J22 | L22: 10546800 | M22: =K22-L22 | N22: {=_xlfn.IFNA(_xlfn.IFS(M22=0,"PAYE",K22=M22,"NON PAYE"),"PARTIEL")} | O22: CHQ-0150-2026 | P22: DECHARGE | Q22: GDIZ
A23: 46254 | B23: 0041-BC-SHEA/NAP-2026 | C23: 1019 | D23: FRS00003 | E23: =_xlfn.XLOOKUP(D23,'CODE FRS'!B:B,'CODE FRS'!C:C) | F23: BP4509RB/AV2192RB | G23: 34908 | H23: 48600 | I23: 461 | J23: 340 | K23: =H23*J23 | L23: 16524000 | M23: =K23-L23 | N23: {=_xlfn.IFNA(_xlfn.IFS(M23=0,"PAYE",K23=M23,"NON PAYE"),"PARTIEL")} | O23: CHQ-0156-2026 | P23: DECHARGE | Q23: GDIZ
A24: 46254 | B24: 0043-BC-SHEA/NAP-2026 | C24: 1020 | D24: FRS00003 | E24: =_xlfn.XLOOKUP(D24,'CODE FRS'!B:B,'CODE FRS'!C:C) | F24: BY1669RB/BY1665RB | G24: 34928 | H24: 44560 | I24: 430 | J24: 335 | K24: =H24*J24 | L24: 14927600 | M24: =K24-L24 | N24: {=_xlfn.IFNA(_xlfn.IFS(M24=0,"PAYE",K24=M24,"NON PAYE"),"PARTIEL")} | O24: CHQ-0156-2026 | P24: DECHARGE | Q24: GDIZ
A25: 46254 | B25: 0022-BC-SHEA/NAP-2026 | C25: 1021 | D25: FRS00009 | E25: =_xlfn.XLOOKUP(D25,'CODE FRS'!B:B,'CODE FRS'!C:C) | F25: BB9793RB/BD3472RB | G25: 34913 | H25: 34980 | I25: 405 | J25: 330 | K25: =H25*J25 | L25: =200000+11343400 | M25: =K25-L25 | N25: {=_xlfn.IFNA(_xlfn.IFS(M25=0,"PAYE",K25=M25,"NON PAYE"),"PARTIEL")} | O25: CC-0071-2026 & CHQ-0153-2026 | P25: DECHARGE | Q25: GDIZ
A26: 46255 | B26: 0045-BC-SHEA/NAP-2026 | C26: 1022 | D26: FRS00011 | E26: =_xlfn.XLOOKUP(D26,'CODE FRS'!B:B,'CODE FRS'!C:C) | F26: CL0201RB/CJ8154RB | G26: 34972 | H26: 45400 | I26: 420 | J26: 330 | K26: =H26*J26 | L26: 14982000 | M26: =K26-L26 | N26: {=_xlfn.IFNA(_xlfn.IFS(M26=0,"PAYE",K26=M26,"NON PAYE"),"PARTIEL")} | O26: CHQ-0160-2026 | P26: DECHARGE | Q26: GDIZ
A27: 46255 | B27: 0049-BC-SHEA/NAP-2026 | C27: 1023 | D27: FRS00004 | E27: =_xlfn.XLOOKUP(D27,'CODE FRS'!B:B,'CODE FRS'!C:C) | F27: CB6790RB/BT1547RB | G27: 34964 | H27: 46160 | I27: 484 | J27: 330 | K27: =H27*J27 | L27: 15232800 | M27: =K27-L27 | N27: {=_xlfn.IFNA(_xlfn.IFS(M27=0,"PAYE",K27=M27,"NON PAYE"),"PARTIEL")} | O27: CHQ-0201-2026 | P27: DECHARGE | Q27: GDIZ
A28: 46255 | B28: 0033-BC-SHEA/NAP-2026 | C28: 1024 | D28: FRS00016 | E28: =_xlfn.XLOOKUP(D28,'CODE FRS'!B:B,'CODE FRS'!C:C) | F28: AP7150RB/AL0466RB | G28: 34989 | H28: 33980 | I28: 336 | J28: 340 | K28: =H28*J28 | L28: =5000000+6553200 | M28: =K28-L28 | N28: {=_xlfn.IFNA(_xlfn.IFS(M28=0,"PAYE",K28=M28,"NON PAYE"),"PARTIEL")} | O28: CC-0075-2026 & CHQ-0159-2026 | P28: DECHARGE | Q28: GDIZ
A29: 46256 | B29: 0051-BC-SHEA/NAP-2026 | C29: 1025 | D29: FRS00001 | E29: =_xlfn.XLOOKUP(D29,'CODE FRS'!B:B,'CODE FRS'!C:C) | F29: BY5570RB/BH1863RB | G29: 34995 | H29: 44400 | I29: 420 | J29: 335 | K29: =H29*J29 | L29: 14874000 | M29: =K29-L29 | N29: {=_xlfn.IFNA(_xlfn.IFS(M29=0,"PAYE",K29=M29,"NON PAYE"),"PARTIEL")} | O29: CHQ-0165-2026 | P29: DECHARGE | Q29: GDIZ
A30: 46256 | B30: 0052-BC-SHEA/NAP-2026 | C30: 1026 | D30: FRS00019 | E30: =_xlfn.XLOOKUP(D30,'CODE FRS'!B:B,'CODE FRS'!C:C) | F30: BY6831RB/BC1375RB | G30: 34996 | H30: 49360 | I30: 460 | J30: 330 | K30: =H30*J30 | L30: 16288800 | M30: =K30-L30 | N30: {=_xlfn.IFNA(_xlfn.IFS(M30=0,"PAYE",K30=M30,"NON PAYE"),"PARTIEL")} | O30: CHQ-0176-2026 | P30: DECHARGE | Q30: GDIZ
A31: 46258 | B31: 0058-BC-SHEA/NAP-2026 | C31: 1027 | D31: FRS00021 | E31: =_xlfn.XLOOKUP(D31,'CODE FRS'!B:B,'CODE FRS'!C:C) | F31: CH2008RB/BA5975RB | G31: 35009 | H31: 44520 | I31: 437 | J31: 330 | K31: =H31*J31 | L31: 14691600 | M31: =K31-L31 | N31: {=_xlfn.IFNA(_xlfn.IFS(M31=0,"PAYE",K31=M31,"NON PAYE"),"PARTIEL")} | O31: CHQ-0173-2026 | P31: DECHARGE | Q31: GDIZ
A32: 46258 | B32: 0032-BC-SHEA/NAP-2026 | C32: 1028 | D32: FRS00015 | E32: =_xlfn.XLOOKUP(D32,'CODE FRS'!B:B,'CODE FRS'!C:C) | F32: AY3969RB/AD0138RB | G32: 35014 | H32: 39620 | I32: 454 | J32: 335 | K32: =H32*J32 | L32: =9000000+4272700 | M32: =K32-L32 | N32: {=_xlfn.IFNA(_xlfn.IFS(M32=0,"PAYE",K32=M32,"NON PAYE"),"PARTIEL")} | O32: CHQ-0162-2026 & CHQ-0168-2026 | P32: DECHARGE | Q32: GDIZ
A33: 46258 | B33: 0063-BC-SHEA/NAP-2026 | C33: 1029 | D33: FRS00022 | E33: =_xlfn.XLOOKUP(D33,'CODE FRS'!B:B,'CODE FRS'!C:C) | F33: BP5945RB/BY8609RB | G33: 35033 | H33: 33740 | I33: 301 | J33: 335 | K33: =H33*J33 | L33: 11302900 | M33: =K33-L33 | N33: {=_xlfn.IFNA(_xlfn.IFS(M33=0,"PAYE",K33=M33,"NON PAYE"),"PARTIEL")} | O33: CHQ-0175-2026 | P33: DECHARGE | Q33: GDIZ
A34: 46258 | B34: 0070-BC-SHEA/NAP-2026 | C34: 1030 | D34: FRS00016 | E34: =_xlfn.XLOOKUP(D34,'CODE FRS'!B:B,'CODE FRS'!C:C) | F34: CA5858RB/AC1719RB | G34: 35036 | H34: 46920 | I34: 479 | J34: 340 | K34: =H34*J34 | L34: 15952800 | M34: =K34-L34 | N34: {=_xlfn.IFNA(_xlfn.IFS(M34=0,"PAYE",K34=M34,"NON PAYE"),"PARTIEL")} | O34: CC-0075-2026 & CHQ-0159-2026 | P34: DECHARGE | Q34: GDIZ
A35: 46259 | C35: 1031 | D35: FRS00031 | E35: =_xlfn.XLOOKUP(D35,'CODE FRS'!B:B,'CODE FRS'!C:C) | F35: BX1108RB/BX1109RB | G35: 35101 | H35: 42160 | I35: 419 | J35: 330 | K35: =H35*J35 | L35: =10000000+3912800 | M35: =K35-L35 | N35: {=_xlfn.IFNA(_xlfn.IFS(M35=0,"PAYE",K35=M35,"NON PAYE"),"PARTIEL")} | O35: CHQ-0174-2026 & CHQ-0189-2026 | P35: DECHARGE | Q35: GDIZ
A36: 46259 | B36: 0064-BC-SHEA/NAP-2026 | C36: 1032 | D36: FRS00006 | E36: =_xlfn.XLOOKUP(D36,'CODE FRS'!B:B,'CODE FRS'!C:C) | F36: CL2204RB/BU2541RB | G36: 35083 | H36: 50320 | I36: 490 | J36: 335 | K36: =H36*J36 | L36: =1000000+5000000+10757200 | M36: =K36-L36 | N36: {=_xlfn.IFNA(_xlfn.IFS(M36=0,"PAYE",K36=M36,"NON PAYE"),"PARTIEL")} | O36: CC-0083-2026 & CC-0094-2026 & CHQ-0190-2026 | P36: DECHARGE | Q36: GDIZ
A37: 46259 | B37: 0027-BC-SHEA/NAP-2026 | C37: 1033 | D37: FRS00013 | E37: =_xlfn.XLOOKUP(D37,'CODE FRS'!B:B,'CODE FRS'!C:C) | F37: BA0693RB/BG9156RB | G37: 35063 | H37: 45300 | I37: 532 | J37: 335 | K37: =H37*J37 | L37: =100000+9000000+6075500 | M37: =K37-L37 | N37: {=_xlfn.IFNA(_xlfn.IFS(M37=0,"PAYE",K37=M37,"NON PAYE"),"PARTIEL")} | O37: CC-0074-2026 & CHQ-0163-2026 & CHQ-0171-2026 | P37: DECHARGE | Q37: GDIZ
A38: 46259 | B38: 0046-BC-SHEA/NAP-2026 | C38: 1034 | D38: FRS00003 | E38: =_xlfn.XLOOKUP(D38,'CODE FRS'!B:B,'CODE FRS'!C:C) | F38: BU0599RB/BC5874RB | G38: 35085 | H38: 20900 | I38: 220 | J38: 345 | K38: =H38*J38 | L38: =5000000+2210500 | M38: =K38-L38 | N38: {=_xlfn.IFNA(_xlfn.IFS(M38=0,"PAYE",K38=M38,"NON PAYE"),"PARTIEL")} | O38: CHQ-0184-2026 & CHQ-0214-2026 | P38: DECHARGE | Q38: GDIZ
A39: 46259 | B39: 0076-BC-SHEA/NAP-2026 | C39: 1035 | D39: FRS00001 | E39: =_xlfn.XLOOKUP(D39,'CODE FRS'!B:B,'CODE FRS'!C:C) | F39: CG4463RB/CE6958RB | G39: 35074 | H39: 42380 | I39: 460 | J39: 335 | K39: =H39*J39 | L39: 14197300 | M39: =K39-L39 | N39: {=_xlfn.IFNA(_xlfn.IFS(M39=0,"PAYE",K39=M39,"NON PAYE"),"PARTIEL")} | O39: CHQ-0167-2026 | P39: DECHARGE | Q39: GDIZ
A40: 46259 | C40: 1036 | D40: FRS00009 | E40: =_xlfn.XLOOKUP(D40,'CODE FRS'!B:B,'CODE FRS'!C:C) | F40: BB9793RB/BD3472RB | G40: 35127 | H40: 2700 | I40: 22 | J40: 330 | K40: =H40*J40 | L40: 891000 | M40: =K40-L40 | N40: {=_xlfn.IFNA(_xlfn.IFS(M40=0,"PAYE",K40=M40,"NON PAYE"),"PARTIEL")} | O40: CHQ-0169-2026 | P40: DECHARGE | Q40: GDIZ
A41: 46259 | B41: 0078-BC-SHEA/NAP-2026 | C41: 1037 | D41: FRS00009 | E41: =_xlfn.XLOOKUP(D41,'CODE FRS'!B:B,'CODE FRS'!C:C) | F41: BD4987RB/BE6187RB | G41: 35124 | H41: 51320 | I41: 475 | J41: 330 | K41: =H41*J41 | L41: =13422400+2900000 | M41: =K41-L41 | N41: {=_xlfn.IFNA(_xlfn.IFS(M41=0,"PAYE",K41=M41,"NON PAYE"),"PARTIEL")} | O41: CHQ-0169-2026 & CHQ-0188-2026 | P41: DECHARGE | Q41: GDIZ
...

Sheet Releve Comptes Fournisseurs
C1: RELEVE DE COMPTES PAR FOURNISSEUR
E3: =SUBTOTAL(9,Table3[Nb BC Passes]) | F3: =SUBTOTAL(9,Table3[Nb rejet]) | G3: =SUBTOTAL(9,Table3[Nb Camions Livres]) | H3: =SUBTOTAL(9,Table3[Poids Net Livre (KG)]) | I3: =SUBTOTAL(9,Table3[Montant Total Du (FCFA)]) | J3: =SUBTOTAL(9,Table3[Montant Paye (FCFA)]) | K3: =SUBTOTAL(9,Table3[Solde Restant Du (FCFA)])
C4: Code FRS | D4: Fournisseur | E4: Nb BC Passes | F4: Nb rejet | G4: Nb Camions Livres | H4: Poids Net Livre (KG) | I4: Montant Total Du (FCFA) | J4: Montant Paye (FCFA) | K4: Solde Restant Du (FCFA) | L4: % Paye
C5: ='CODE FRS'!B4 | D5: =_xlfn.XLOOKUP(C5,'CODE FRS'!B:B,'CODE FRS'!C:C) | E5: =COUNTIF('Bons de Commande'!E:E,Table3[[#This Row],[Code FRS]]) | F5: =COUNTIFS(Table1[Statut Livraison],"REJETE",Table1[Fournisseur],Table3[[#This Row],[Fournisseur]]) | G5: =COUNTIF('Commandes Dechargees'!D:D,Table3[[#This Row],[Code FRS]]) | H5: =SUMIFS('Commandes Dechargees'!H:H,'Commandes Dechargees'!D:D,Table3[[#This Row],[Code FRS]]) | I5: =SUMIFS('Commandes Dechargees'!K:K,'Commandes Dechargees'!D:D,Table3[[#This Row],[Code FRS]]) | J5: =SUMIFS('Commandes Dechargees'!L:L,'Commandes Dechargees'!D:D,Table3[[#This Row],[Code FRS]]) | K5: =I5-J5 | L5: =IFERROR(J5/I5,0)
C6: ='CODE FRS'!B5 | D6: =_xlfn.XLOOKUP(C6,'CODE FRS'!B:B,'CODE FRS'!C:C) | E6: =COUNTIF('Bons de Commande'!E:E,Table3[[#This Row],[Code FRS]]) | F6: =COUNTIFS(Table1[Statut Livraison],"REJETE",Table1[Fournisseur],Table3[[#This Row],[Fournisseur]]) | G6: =COUNTIF('Commandes Dechargees'!D:D,Table3[[#This Row],[Code FRS]]) | H6: =SUMIFS('Commandes Dechargees'!H:H,'Commandes Dechargees'!D:D,Table3[[#This Row],[Code FRS]]) | I6: =SUMIFS('Commandes Dechargees'!K:K,'Commandes Dechargees'!D:D,Table3[[#This Row],[Code FRS]]) | J6: =SUMIFS('Commandes Dechargees'!L:L,'Commandes Dechargees'!D:D,Table3[[#This Row],[Code FRS]]) | K6: =I6-J6 | L6: =IFERROR(J6/I6,0)
C7: ='CODE FRS'!B6 | D7: =_xlfn.XLOOKUP(C7,'CODE FRS'!B:B,'CODE FRS'!C:C) | E7: =COUNTIF('Bons de Commande'!E:E,Table3[[#This Row],[Code FRS]]) | F7: =COUNTIFS(Table1[Statut Livraison],"REJETE",Table1[Fournisseur],Table3[[#This Row],[Fournisseur]]) | G7: =COUNTIF('Commandes Dechargees'!D:D,Table3[[#This Row],[Code FRS]]) | H7: =SUMIFS('Commandes Dechargees'!H:H,'Commandes Dechargees'!D:D,Table3[[#This Row],[Code FRS]]) | I7: =SUMIFS('Commandes Dechargees'!K:K,'Commandes Dechargees'!D:D,Table3[[#This Row],[Code FRS]]) | J7: =SUMIFS('Commandes Dechargees'!L:L,'Commandes Dechargees'!D:D,Table3[[#This Row],[Code FRS]]) | K7: =I7-J7 | L7: =IFERROR(J7/I7,0)
C8: ='CODE FRS'!B7 | D8: =_xlfn.XLOOKUP(C8,'CODE FRS'!B:B,'CODE FRS'!C:C) | E8: =COUNTIF('Bons de Commande'!E:E,Table3[[#This Row],[Code FRS]]) | F8: =COUNTIFS(Table1[Statut Livraison],"REJETE",Table1[Fournisseur],Table3[[#This Row],[Fournisseur]]) | G8: =COUNTIF('Commandes Dechargees'!D:D,Table3[[#This Row],[Code FRS]]) | H8: =SUMIFS('Commandes Dechargees'!H:H,'Commandes Dechargees'!D:D,Table3[[#This Row],[Code FRS]]) | I8: =SUMIFS('Commandes Dechargees'!K:K,'Commandes Dechargees'!D:D,Table3[[#This Row],[Code FRS]]) | J8: =SUMIFS('Commandes Dechargees'!L:L,'Commandes Dechargees'!D:D,Table3[[#This Row],[Code FRS]]) | K8: =I8-J8 | L8: =IFERROR(J8/I8,0)
C9: ='CODE FRS'!B8 | D9: =_xlfn.XLOOKUP(C9,'CODE FRS'!B:B,'CODE FRS'!C:C) | E9: =COUNTIF('Bons de Commande'!E:E,Table3[[#This Row],[Code FRS]]) | F9: =COUNTIFS(Table1[Statut Livraison],"REJETE",Table1[Fournisseur],Table3[[#This Row],[Fournisseur]]) | G9: =COUNTIF('Commandes Dechargees'!D:D,Table3[[#This Row],[Code FRS]]) | H9: =SUMIFS('Commandes Dechargees'!H:H,'Commandes Dechargees'!D:D,Table3[[#This Row],[Code FRS]]) | I9: =SUMIFS('Commandes Dechargees'!K:K,'Commandes Dechargees'!D:D,Table3[[#This Row],[Code FRS]]) | J9: =SUMIFS('Commandes Dechargees'!L:L,'Commandes Dechargees'!D:D,Table3[[#This Row],[Code FRS]]) | K9: =I9-J9 | L9: =IFERROR(J9/I9,0)
C10: ='CODE FRS'!B9 | D10: =_xlfn.XLOOKUP(C10,'CODE FRS'!B:B,'CODE FRS'!C:C) | E10: =COUNTIF('Bons de Commande'!E:E,Table3[[#This Row],[Code FRS]]) | F10: =COUNTIFS(Table1[Statut Livraison],"REJETE",Table1[Fournisseur],Table3[[#This Row],[Fournisseur]]) | G10: =COUNTIF('Commandes Dechargees'!D:D,Table3[[#This Row],[Code FRS]]) | H10: =SUMIFS('Commandes Dechargees'!H:H,'Commandes Dechargees'!D:D,Table3[[#This Row],[Code FRS]]) | I10: =SUMIFS('Commandes Dechargees'!K:K,'Commandes Dechargees'!D:D,Table3[[#This Row],[Code FRS]]) | J10: =SUMIFS('Commandes Dechargees'!L:L,'Commandes Dechargees'!D:D,Table3[[#This Row],[Code FRS]]) | K10: =I10-J10 | L10: =IFERROR(J10/I10,0)
C11: ='CODE FRS'!B10 | D11: =_xlfn.XLOOKUP(C11,'CODE FRS'!B:B,'CODE FRS'!C:C) | E11: =COUNTIF('Bons de Commande'!E:E,Table3[[#This Row],[Code FRS]]) | F11: =COUNTIFS(Table1[Statut Livraison],"REJETE",Table1[Fournisseur],Table3[[#This Row],[Fournisseur]]) | G11: =COUNTIF('Commandes Dechargees'!D:D,Table3[[#This Row],[Code FRS]]) | H11: =SUMIFS('Commandes Dechargees'!H:H,'Commandes Dechargees'!D:D,Table3[[#This Row],[Code FRS]]) | I11: =SUMIFS('Commandes Dechargees'!K:K,'Commandes Dechargees'!D:D,Table3[[#This Row],[Code FRS]]) | J11: =SUMIFS('Commandes Dechargees'!L:L,'Commandes Dechargees'!D:D,Table3[[#This Row],[Code FRS]]) | K11: =I11-J11 | L11: =IFERROR(J11/I11,0)
C12: ='CODE FRS'!B11 | D12: =_xlfn.XLOOKUP(C12,'CODE FRS'!B:B,'CODE FRS'!C:C) | E12: =COUNTIF('Bons de Commande'!E:E,Table3[[#This Row],[Code FRS]]) | F12: =COUNTIFS(Table1[Statut Livraison],"REJETE",Table1[Fournisseur],Table3[[#This Row],[Fournisseur]]) | G12: =COUNTIF('Commandes Dechargees'!D:D,Table3[[#This Row],[Code FRS]]) | H12: =SUMIFS('Commandes Dechargees'!H:H,'Commandes Dechargees'!D:D,Table3[[#This Row],[Code FRS]]) | I12: =SUMIFS('Commandes Dechargees'!K:K,'Commandes Dechargees'!D:D,Table3[[#This Row],[Code FRS]]) | J12: =SUMIFS('Commandes Dechargees'!L:L,'Commandes Dechargees'!D:D,Table3[[#This Row],[Code FRS]]) | K12: =I12-J12 | L12: =IFERROR(J12/I12,0)
C13: ='CODE FRS'!B12 | D13: =_xlfn.XLOOKUP(C13,'CODE FRS'!B:B,'CODE FRS'!C:C) | E13: =COUNTIF('Bons de Commande'!E:E,Table3[[#This Row],[Code FRS]]) | F13: =COUNTIFS(Table1[Statut Livraison],"REJETE",Table1[Fournisseur],Table3[[#This Row],[Fournisseur]]) | G13: =COUNTIF('Commandes Dechargees'!D:D,Table3[[#This Row],[Code FRS]]) | H13: =SUMIFS('Commandes Dechargees'!H:H,'Commandes Dechargees'!D:D,Table3[[#This Row],[Code FRS]]) | I13: =SUMIFS('Commandes Dechargees'!K:K,'Commandes Dechargees'!D:D,Table3[[#This Row],[Code FRS]]) | J13: =SUMIFS('Commandes Dechargees'!L:L,'Commandes Dechargees'!D:D,Table3[[#This Row],[Code FRS]]) | K13: =I13-J13 | L13: =IFERROR(J13/I13,0)
C14: ='CODE FRS'!B13 | D14: =_xlfn.XLOOKUP(C14,'CODE FRS'!B:B,'CODE FRS'!C:C) | E14: =COUNTIF('Bons de Commande'!E:E,Table3[[#This Row],[Code FRS]]) | F14: =COUNTIFS(Table1[Statut Livraison],"REJETE",Table1[Fournisseur],Table3[[#This Row],[Fournisseur]]) | G14: =COUNTIF('Commandes Dechargees'!D:D,Table3[[#This Row],[Code FRS]]) | H14: =SUMIFS('Commandes Dechargees'!H:H,'Commandes Dechargees'!D:D,Table3[[#This Row],[Code FRS]]) | I14: =SUMIFS('Commandes Dechargees'!K:K,'Commandes Dechargees'!D:D,Table3[[#This Row],[Code FRS]]) | J14: =SUMIFS('Commandes Dechargees'!L:L,'Commandes Dechargees'!D:D,Table3[[#This Row],[Code FRS]]) | K14: =I14-J14 | L14: =IFERROR(J14/I14,0)
C15: ='CODE FRS'!B14 | D15: =_xlfn.XLOOKUP(C15,'CODE FRS'!B:B,'CODE FRS'!C:C) | E15: =COUNTIF('Bons de Commande'!E:E,Table3[[#This Row],[Code FRS]]) | F15: =COUNTIFS(Table1[Statut Livraison],"REJETE",Table1[Fournisseur],Table3[[#This Row],[Fournisseur]]) | G15: =COUNTIF('Commandes Dechargees'!D:D,Table3[[#This Row],[Code FRS]]) | H15: =SUMIFS('Commandes Dechargees'!H:H,'Commandes Dechargees'!D:D,Table3[[#This Row],[Code FRS]]) | I15: =SUMIFS('Commandes Dechargees'!K:K,'Commandes Dechargees'!D:D,Table3[[#This Row],[Code FRS]]) | J15: =SUMIFS('Commandes Dechargees'!L:L,'Commandes Dechargees'!D:D,Table3[[#This Row],[Code FRS]]) | K15: =I15-J15 | L15: =IFERROR(J15/I15,0)
C16: ='CODE FRS'!B15 | D16: =_xlfn.XLOOKUP(C16,'CODE FRS'!B:B,'CODE FRS'!C:C) | E16: =COUNTIF('Bons de Commande'!E:E,Table3[[#This Row],[Code FRS]]) | F16: =COUNTIFS(Table1[Statut Livraison],"REJETE",Table1[Fournisseur],Table3[[#This Row],[Fournisseur]]) | G16: =COUNTIF('Commandes Dechargees'!D:D,Table3[[#This Row],[Code FRS]]) | H16: =SUMIFS('Commandes Dechargees'!H:H,'Commandes Dechargees'!D:D,Table3[[#This Row],[Code FRS]]) | I16: =SUMIFS('Commandes Dechargees'!K:K,'Commandes Dechargees'!D:D,Table3[[#This Row],[Code FRS]]) | J16: =SUMIFS('Commandes Dechargees'!L:L,'Commandes Dechargees'!D:D,Table3[[#This Row],[Code FRS]]) | K16: =I16-J16 | L16: =IFERROR(J16/I16,0)
... C50: ='CODE FRS'!B49 | D50: =_xlfn.XLOOKUP(C50,'CODE FRS'!B:B,'CODE FRS'!C:C) | E50: =COUNTIF('Bons de Commande'!E:E,Table3[[#This Row],[Code FRS]]) | F50: =COUNTIFS(Table1[Statut Livraison],"REJETE",Table1[Fournisseur],Table3[[#This Row],[Fournisseur]]) | G50: =COUNTIF('Commandes Dechargees'!D:D,Table3[[#This Row],[Code FRS]]) | H50: =SUMIFS('Commandes Dechargees'!H:H,'Commandes Dechargees'!D:D,Table3[[#This Row],[Code FRS]]) | I50: =SUMIFS('Commandes Dechargees'!K:K,'Commandes Dechargees'!D:D,Table3[[#This Row],[Code FRS]]) | J50: =SUMIFS('Commandes Dechargees'!L:L,'Commandes Dechargees'!D:D,Table3[[#This Row],[Code FRS]]) | K50: =I50-J50 | L50: =IFERROR(J50/I50,0)
